2023-09-02 10:27:39,959 INFO    StreamThr :21104 [internal.py:wandb_internal():86] W&B internal server running at pid: 21104, started at: 2023-09-02 10:27:39.958522
2023-09-02 10:27:39,965 DEBUG   HandlerThread:21104 [handler.py:handle_request():144] handle_request: status
2023-09-02 10:27:39,973 INFO    WriterThread:21104 [datastore.py:open_for_write():85] open: /home/jayaram/research/NLP_course_papers_and_content/Assignments/Assign_1/wandb/run-20230902_102739-LSTM_training_1/run-LSTM_training_1.wandb
2023-09-02 10:27:39,975 DEBUG   SenderThread:21104 [sender.py:send():379] send: header
2023-09-02 10:27:40,003 DEBUG   SenderThread:21104 [sender.py:send():379] send: run
2023-09-02 10:27:43,684 INFO    SenderThread:21104 [retry.py:__call__():172] Retry attempt failed:
Traceback (most recent call last):
  File "/home/jayaram/miniconda3/envs/Advanced_NLP/lib/python3.9/site-packages/urllib3/connection.py", line 174, in _new_conn
    conn = connection.create_connection(
  File "/home/jayaram/miniconda3/envs/Advanced_NLP/lib/python3.9/site-packages/urllib3/util/connection.py", line 72, in create_connection
    for res in socket.getaddrinfo(host, port, family, socket.SOCK_STREAM):
  File "/home/jayaram/miniconda3/envs/Advanced_NLP/lib/python3.9/socket.py", line 954, in getaddrinfo
    for res in _socket.getaddrinfo(host, port, family, type, proto, flags):
socket.gaierror: [Errno -3] Temporary failure in name resolution

During handling of the above exception, another exception occurred:

Traceback (most recent call last):
  File "/home/jayaram/miniconda3/envs/Advanced_NLP/lib/python3.9/site-packages/urllib3/connectionpool.py", line 714, in urlopen
    httplib_response = self._make_request(
  File "/home/jayaram/miniconda3/envs/Advanced_NLP/lib/python3.9/site-packages/urllib3/connectionpool.py", line 403, in _make_request
    self._validate_conn(conn)
  File "/home/jayaram/miniconda3/envs/Advanced_NLP/lib/python3.9/site-packages/urllib3/connectionpool.py", line 1053, in _validate_conn
    conn.connect()
  File "/home/jayaram/miniconda3/envs/Advanced_NLP/lib/python3.9/site-packages/urllib3/connection.py", line 363, in connect
    self.sock = conn = self._new_conn()
  File "/home/jayaram/miniconda3/envs/Advanced_NLP/lib/python3.9/site-packages/urllib3/connection.py", line 186, in _new_conn
    raise NewConnectionError(
urllib3.exceptions.NewConnectionError: <urllib3.connection.HTTPSConnection object at 0x7f202403b340>: Failed to establish a new connection: [Errno -3] Temporary failure in name resolution

During handling of the above exception, another exception occurred:

Traceback (most recent call last):
  File "/home/jayaram/miniconda3/envs/Advanced_NLP/lib/python3.9/site-packages/requests/adapters.py", line 486, in send
    resp = conn.urlopen(
  File "/home/jayaram/miniconda3/envs/Advanced_NLP/lib/python3.9/site-packages/urllib3/connectionpool.py", line 798, in urlopen
    retries = retries.increment(
  File "/home/jayaram/miniconda3/envs/Advanced_NLP/lib/python3.9/site-packages/urllib3/util/retry.py", line 592, in increment
    raise MaxRetryError(_pool, url, error or ResponseError(cause))
urllib3.exceptions.MaxRetryError: HTTPSConnectionPool(host='api.wandb.ai', port=443): Max retries exceeded with url: /graphql (Caused by NewConnectionError('<urllib3.connection.HTTPSConnection object at 0x7f202403b340>: Failed to establish a new connection: [Errno -3] Temporary failure in name resolution'))

During handling of the above exception, another exception occurred:

Traceback (most recent call last):
  File "/home/jayaram/miniconda3/envs/Advanced_NLP/lib/python3.9/site-packages/wandb/sdk/lib/retry.py", line 131, in __call__
    result = self._call_fn(*args, **kwargs)
  File "/home/jayaram/miniconda3/envs/Advanced_NLP/lib/python3.9/site-packages/wandb/sdk/internal/internal_api.py", line 323, in execute
    return self.client.execute(*args, **kwargs)  # type: ignore
  File "/home/jayaram/miniconda3/envs/Advanced_NLP/lib/python3.9/site-packages/wandb/vendor/gql-0.2.0/wandb_gql/client.py", line 52, in execute
    result = self._get_result(document, *args, **kwargs)
  File "/home/jayaram/miniconda3/envs/Advanced_NLP/lib/python3.9/site-packages/wandb/vendor/gql-0.2.0/wandb_gql/client.py", line 60, in _get_result
    return self.transport.execute(document, *args, **kwargs)
  File "/home/jayaram/miniconda3/envs/Advanced_NLP/lib/python3.9/site-packages/wandb/sdk/lib/gql_request.py", line 55, in execute
    request = self.session.post(self.url, **post_args)
  File "/home/jayaram/miniconda3/envs/Advanced_NLP/lib/python3.9/site-packages/requests/sessions.py", line 637, in post
    return self.request("POST", url, data=data, json=json, **kwargs)
  File "/home/jayaram/miniconda3/envs/Advanced_NLP/lib/python3.9/site-packages/requests/sessions.py", line 589, in request
    resp = self.send(prep, **send_kwargs)
  File "/home/jayaram/miniconda3/envs/Advanced_NLP/lib/python3.9/site-packages/requests/sessions.py", line 703, in send
    r = adapter.send(request, **kwargs)
  File "/home/jayaram/miniconda3/envs/Advanced_NLP/lib/python3.9/site-packages/requests/adapters.py", line 519, in send
    raise ConnectionError(e, request=request)
requests.exceptions.ConnectionError: HTTPSConnectionPool(host='api.wandb.ai', port=443): Max retries exceeded with url: /graphql (Caused by NewConnectionError('<urllib3.connection.HTTPSConnection object at 0x7f202403b340>: Failed to establish a new connection: [Errno -3] Temporary failure in name resolution'))
2023-09-02 10:27:45,007 DEBUG   HandlerThread:21104 [handler.py:handle_request():144] handle_request: keepalive
2023-09-02 10:27:50,011 DEBUG   HandlerThread:21104 [handler.py:handle_request():144] handle_request: keepalive
2023-09-02 10:27:55,014 DEBUG   HandlerThread:21104 [handler.py:handle_request():144] handle_request: keepalive
2023-09-02 10:28:00,018 DEBUG   HandlerThread:21104 [handler.py:handle_request():144] handle_request: keepalive
2023-09-02 10:28:05,021 DEBUG   HandlerThread:21104 [handler.py:handle_request():144] handle_request: keepalive
2023-09-02 10:28:10,025 DEBUG   HandlerThread:21104 [handler.py:handle_request():144] handle_request: keepalive
2023-09-02 10:28:15,028 DEBUG   HandlerThread:21104 [handler.py:handle_request():144] handle_request: keepalive
2023-09-02 10:28:20,032 DEBUG   HandlerThread:21104 [handler.py:handle_request():144] handle_request: keepalive
2023-09-02 10:28:25,035 DEBUG   HandlerThread:21104 [handler.py:handle_request():144] handle_request: keepalive
2023-09-02 10:28:30,039 DEBUG   HandlerThread:21104 [handler.py:handle_request():144] handle_request: keepalive
2023-09-02 10:28:35,042 DEBUG   HandlerThread:21104 [handler.py:handle_request():144] handle_request: keepalive
2023-09-02 10:28:40,045 DEBUG   HandlerThread:21104 [handler.py:handle_request():144] handle_request: cancel
2023-09-02 10:28:40,046 DEBUG   HandlerThread:21104 [handler.py:handle_request():144] handle_request: cancel
2023-09-02 10:28:40,047 DEBUG   SenderThread:21104 [sender.py:send():388] Record cancelled: run
2023-09-02 10:28:40,049 DEBUG   HandlerThread:21104 [handler.py:handle_request():144] handle_request: status_report
